[32mINFO    [0m himool_auto_case:api_client.py:34 API客户端初始化完成，base_url: http://test-api.example.com/api
[32mINFO    [0m himool_auto_case:test_add_user.py:42 开始测试添加用户接口，测试数据: {'username': 'testuser6933', 'name': '测试用户6933', 'phone': '13800006933', 'email': 'test6933@example.com', 'sex': 'man', 'roles': [1], 'is_active': True}
[32mINFO    [0m himool_auto_case:api_client.py:54 API请求: POST http://localhost:8081/api/users
[31m[1mERROR   [0m himool_auto_case:api_client.py:125 请求异常: HTTPConnectionPool(host='localhost', port=8081): Max retries exceeded with url: /api/users (Caused by NewConnectionError('<urllib3.connection.HTTPConnection object at 0x1104b1ac0>: Failed to establish a new connection: [Errno 61] Connection refused'))
[32mINFO    [0m himool_auto_case:api_client.py:127 重试请求 (1/3)
[31m[1mERROR   [0m himool_auto_case:api_client.py:125 请求异常: HTTPConnectionPool(host='localhost', port=8081): Max retries exceeded with url: /api/users (Caused by NewConnectionError('<urllib3.connection.HTTPConnection object at 0x1104b1e50>: Failed to establish a new connection: [Errno 61] Connection refused'))
[32mINFO    [0m himool_auto_case:api_client.py:127 重试请求 (2/3)
[31m[1mERROR   [0m himool_auto_case:api_client.py:125 请求异常: HTTPConnectionPool(host='localhost', port=8081): Max retries exceeded with url: /api/users (Caused by NewConnectionError('<urllib3.connection.HTTPConnection object at 0x1104be280>: Failed to establish a new connection: [Errno 61] Connection refused'))