{"name": "登录后获取用户信息", "status": "failed", "statusDetails": {"message": "AssertionError: 获取用户信息失败: None\nassert None == 0\n +  where None = <built-in method get of dict object at 0x104cc5380>('code')\n +    where <built-in method get of dict object at 0x104cc5380> = {'error': \"HTTPConnectionPool(host='localhost', port=8081): Max retries exceeded with url: /user/info (Caused by NewConnectionError('<urllib3.connection.HTTPConnection object at 0x104a71eb0>: Failed to establish a new connection: [Errno 61] Connection refused'))\"}.get", "trace": "self = <test_demo_api.TestUserAPI object at 0x104b8c4f0>, logged_in_api_client = <common.api_client.APIClient object at 0x104ba8e50>\n\n    @allure.story(\"登录接口\")\n    @allure.title(\"登录后获取用户信息\")\n    @pytest.mark.dependency(depends=[\"test_login_with_valid_credentials\"])\n    def test_get_user_info_after_login(self, logged_in_api_client):\n        \"\"\"测试登录后获取用户信息\"\"\"\n        # 获取用户信息\n        with allure.step(\"获取用户信息\"):\n            response = logged_in_api_client.get(\"/user/info\")\n    \n        # 断言响应\n        with allure.step(\"验证用户信息\"):\n>           assert response.get('code') == 0, f\"获取用户信息失败: {response.get('message')}\"\nE           AssertionError: 获取用户信息失败: None\nE           assert None == 0\nE            +  where None = <built-in method get of dict object at 0x104cc5380>('code')\nE            +    where <built-in method get of dict object at 0x104cc5380> = {'error': \"HTTPConnectionPool(host='localhost', port=8081): Max retries exceeded with url: /user/info (Caused by NewConnectionError('<urllib3.connection.HTTPConnection object at 0x104a71eb0>: Failed to establish a new connection: [Errno 61] Connection refused'))\"}.get\n\ntest_cases/api/test_demo_api.py:127: AssertionError"}, "description": "测试登录后获取用户信息", "steps": [{"name": "获取用户信息", "status": "passed", "start": 1742991641593, "stop": 1742991641594}, {"name": "验证用户信息", "status": "failed", "statusDetails": {"message": "AssertionError: 获取用户信息失败: None\nassert None == 0\n +  where None = <built-in method get of dict object at 0x104cc5380>('code')\n +    where <built-in method get of dict object at 0x104cc5380> = {'error': \"HTTPConnectionPool(host='localhost', port=8081): Max retries exceeded with url: /user/info (Caused by NewConnectionError('<urllib3.connection.HTTPConnection object at 0x104a71eb0>: Failed to establish a new connection: [Errno 61] Connection refused'))\"}.get\n", "trace": "  File \"/Users/Apple/PycharmProjects/himool_auto_case/test_cases/api/test_demo_api.py\", line 127, in test_get_user_info_after_login\n    assert response.get('code') == 0, f\"获取用户信息失败: {response.get('message')}\"\n"}, "start": 1742991641594, "stop": 1742991641594}], "attachments": [{"name": "stderr", "source": "9ac0ebff-2667-4c58-b414-718ea269bd16-attachment.txt", "type": "text/plain"}], "start": 1742991641593, "stop": 1742991641594, "uuid": "fa0eda7a-280a-4237-b8a0-3ad50af1bdc8", "historyId": "eb5e462ee15c36f120d49cab3cb8ec8f", "testCaseId": "eb5e462ee15c36f120d49cab3cb8ec8f", "fullName": "test_cases.api.test_demo_api.TestUserAPI#test_get_user_info_after_login", "labels": [{"name": "feature", "value": "用户管理"}, {"name": "story", "value": "登录接口"}, {"name": "epic", "value": "API测试"}, {"name": "tag", "value": "dependency(depends=['test_login_with_valid_credentials'])"}, {"name": "parentSuite", "value": "test_cases.api"}, {"name": "suite", "value": "test_demo_api"}, {"name": "subSuite", "value": "TestUserAPI"}, {"name": "host", "value": "MacBook-Pro.local"}, {"name": "thread", "value": "78732-MainThread"}, {"name": "framework", "value": "pytest"}, {"name": "language", "value": "cpython3"}, {"name": "package", "value": "test_cases.api.test_demo_api"}]}